import {
  ConflictException,
  InternalServerErrorException,
} from '@nestjs/common';
import { EntityRepository, Repository } from 'typeorm';
import { AuthCredentialsDto } from '../dto/auth-credential.dto';
import { User } from '../entity/user.entity';
import * as bcrypt from 'bcrypt';

@EntityRepository(User)
export class UsersRepository extends Repository<User> {
  async createUser(authCredentialsDto: AuthCredentialsDto): Promise<void> {
    const { username, password } = authCredentialsDto;

    const salt = await bcrypt.genSalt();
    const hashedPassword = await bcrypt.hash(password, salt);
    console.log('HashedPassword :', hashedPassword);
    const user = this.create({ username, password: hashedPassword });

    try {
      console.log('user saved');
      await this.save(user);
    } catch (error) {
      if (error.code === '23505') {
        throw new ConflictException('Username already exists');
      } else {
        throw new InternalServerErrorException();
      }
      console.log(error.code);
    }
  }
}
